File: ASG1_1.XRDML
<?xml version="1.0" encoding="UTF-8"?>
<xrdMeasurements xmlns="http://www.xrdml.com/XRDMeasurement/1.5" xmlns:xsi="http://www.w3.org/2001/XMLSchema-instance" xsi:schemaLocation="http://www.xrdml.com/XRDMeasurement/1.5 http://www.xrdml.com/XRDMeasurement/1.5/XRDMeasurement.xsd" status="Completed">
	<comment>
		<entry>Configuration=Reflection/Transmission, Owner=paul, Creation date=20/02/2013 12:06:42</entry>
		<entry>Goniometer=Omega/2Theta; Minimum step size 2Theta:0.0001; Minimum step size Omega:0.0001</entry>
		<entry>Sample stage=Reflection-transmission spinner; Minimum step size Phi:0.1</entry>
		<entry>Diffractometer system=EMPYREAN</entry>
		<entry>Measurement program=C:\PANalytical\Data Collector\Programs\John 5-90 1hr.xrdmp, Identifier={03C9B423-87C1-47B7-87E4-6B1805CFB0B6}</entry>
		<entry>Fine Calibration Offset for 2Theta = -0.0467 deg</entry>
		<entry>Batch program=C:\PANalytical\Data Collector\Programs\091024.xrdmp, Identifier={3C4B32C6-FFE4-4DFD-8179-9923AADEAB95}</entry>
		<entry/>
	</comment>
	<xrdMeasurement measurementType="Scan" status="Completed" sampleMode="Reflection">
		<usedWavelength intended="K-Alpha 1">
			<kAlpha1 unit="Angstrom">1.540598</kAlpha1>
			<kAlpha2 unit="Angstrom">1.544426</kAlpha2>
			<kBeta unit="Angstrom">1.392250</kBeta>
			<ratioKAlpha2KAlpha1>0.000000</ratioKAlpha2KAlpha1>
		</usedWavelength>
		<incidentBeamPath>
			<radius unit="mm">240.000</radius>
			<xRayTube>
				<tension unit="kV">45</tension>
				<current unit="mA">40</current>
				<anodeMaterial>Cu</anodeMaterial>
			</xRayTube>
			<divergenceSlit xsi:type="fixedDivergenceSlitType">
				<angle unit="deg">1.000</angle>
			</divergenceSlit>
		</incidentBeamPath>
		<diffractedBeamPath>
			<radius unit="mm">240.000</radius>
			<receivingSlit>
				<height unit="mm">0.100</height>
			</receivingSlit>
		</diffractedBeamPath>
		<scan appendNumber="0" mode="Continuous" scanAxis="Gonio" status="Completed">
			<header>
				<startTimeStamp>2024-10-09T22:21:58</startTimeStamp>
				<author>
					<name>Paul</name>
				</author>
				<source>
					<applicationSoftware version="3.0.5">HighScore Plus</applicationSoftware>
				</source>
			</header>
			<dataPoints>
				<positions axis="2Theta" unit="deg">
					<startPosition>5.015</startPosition>
					<endPosition>89.981</endPosition>
				</positions>
				<commonCountingTime unit="seconds">86.995</commonCountingTime>
				<intensities unit="counts">823 720 970 945 735 1067 906 928 804 839 936 865 945 967 866 914 880 768 762 845 896 871 827 794 900 853 852 904 862 868 827 823 886 848 861 901 798 802 795 792 766 844 783 775 809 840 799 852 776 790 844 856 855 771 670 838 876 772 600 694 702 753 732 766 614 699 779 583 704 742 718 793 789 798 751 670 749 699 668 722 674 658 641 668 651 648 720 732 653 679 681 716 674 672 618 602 736 729 762 733 708 531 708 692 615 646 638 627 581 833 670 641 704 746 652 750 653 598 665 548 697 640 650 580 537 610 624 594 626 674 693 647 585 621 604 635 589 630 587 550 544 551 581 542 559 597 525 582 653 592 530 528 544 514 526 549 560 589 567 554 567 570 574 584 564 543 513 573 635 539 546 592 440 674 614 541 518 559 499 548 657 616 536 596 489 585 529 498 600 584 646 582 525 504 512 510 564 541 508 551 536 523 479 472 524 520 497 440 437 441 438 560 514 464 501 492 473 564 451 420 493 527 448 454 448 407 451 405 435 581 466 446 456 516 585 409 392 435 477 474 460 460 449 504 497 444 366 391 410 486 468 459 391 419 498 522 472 462 485 443 418 407 399 428 422 454 452 401 472 486 515 400 411 457 433 436 429 433 359 453 411 368 435 423 438 398 412 413 488 431 415 397 435 466 457 423 477 423 411 426 346 372 398 392 381 407 408 404 406 412 415 416 408 393 419 514 466 376 401 382 373 416 448 400 416 426 390 354 365 361 356 367 366 331 340 385 362 365 381 399 374 429 431 311 384 317 412 366 496 386 357 387 408 369 320 372 404 353 341 361 378 350 351 363 309 343 446 459 392 392 339 310 337 391 387 377 382 381 399 318 292 361 341 329 355 367 372 322 345 364 357 358 342 321 343 318 425 323 320 377 334 356 280 330 320 339 280 399 395 331 349 316 369 295 334 314 335 270 285 348 376 333 291 321 363 358 339 388 341 331 309 306 345 329 307 298 337 324 268 272 278 323 334 317 311 294 316 273 330 334 280 305 330 289 318 311 292 303 311 318 265 313 296 284 357 305 288 325 301 266 263 315 276 280 316 315 265 283 357 316 288 312 300 257 282 275 273 234 277 331 318 322 295 268 297 310 291 266 300 266 237 232 285 315 265 290 237 279 267 299 275 273 238 258 302 286 337 257 317 269 295 281 297 275 407 332 257 276 254 271 274 301 284 286 248 269 294 329 304 284 330 379 376 373 410 465 515 645 752 736 717 786 782 720 622 524 441 383 347 326 319 292 271 238 245 283 257 236 268 256 288 272 271 277 277 277 289 254 237 250 297 263 292 253 235 261 261 243 258 275 241 237 219 238 237 221 208 193 214 229 238 262 295 292 272 268 260 275 270 238 213 228 241 258 260 234 215 211 245 254 233 217 266 239 203 231 260 274 263 226 267 253 225 254 212 263 265 225 250 278 189 206 216 258 219 204 263 239 245 241 198 201 211 218 223 220 228 249 232 208 209 194 196 230 217 230 227 208 238 225 200 230 236 240 277 265 213 208 213 257 251 195 216 233 187 220 213 203 235 203 175 181 217 190 223 231 176 243 246 258 235 216 194 207 161 200 195 207 222 240 184 222 176 185 198 185 202 209 211 215 191 189 196 195 216 218 198 194 191 186 189 199 205 210 227 228 241 235 220 174 181 201 180 230 212 157 186 195 191 193 232 215 249 224 189 196 222 199 196 190 224 211 222 223 187 215 205 186 178 187 238 228 184 186 204 191 190 202 219 183 177 179 179 155 148 170 180 177 164 176 189 163 193 208 223 204 191 182 165 196 192 167 170 209 177 170 177 253 186 145 177 169 144 170 132 160 204 176 165 197 210 192 199 209 187 177 206 182 221 235 248 259 337 398 454 458 446 492 461 420 367 278 247 231 202 187 155 171 201 191 187 179 168 191 185 157 207 166 171 177 181 188 187 173 183 186 207 153 193 197 168 179 168 177 169 147 180 189 191 150 176 184 178 145 139 151 175 173 132 156 165 172 209 199 178 198 240 275 313 352 430 507 542 621 679 750 712 613 453 329 295 250 219 199 191 201 185 180 178 165 224 146 157 170 154 167 214 220 169 149 167 194 180 157 183 160 176 172 176 140 153 146 155 158 154 124 156 147 135 160 155 157 159 150 169 167 155 154 155 158 171 180 174 173 174 160 167 167 156 163 154 150 164 161 133 139 148 138 152 160 183 136 159 149 158 175 159 136 143 161 159 165 119 159 172 160 151 164 141 170 160 136 162 171 171 135 147 182 184 153 151 154 156 155 169 168 150 150 141 150 160 150 155 173 156 145 146 175 155 144 151 156 151 153 174 162 156 148 125 184 158 147 130 150 123 126 183 189 168 144 177 183 160 173 162 154 160 175 178 166 172 165 174 210 175 144 171 203 182 176 213 270 344 396 457 575 776 1046 1360 1611 1903 2055 1918 1632 1306 958 620 431 310 273 236 165 205 199 150 187 163 138 161 143 129 149 147 158 143 135 159 145 149 136 125 158 149 122 134 115 139 146 166 156 148 134 144 148 135 147 150 147 148 131 129 145 156 142 139 150 163 158 150 145 137 146 155 136 156 144 118 133 141 133 137 148 125 133 130 113 150 124 143 120 133 145 143 153 145 147 148 177 147 149 150 167 169 170 158 133 139 155 154 206 202 205 206 184 172 190 213 219 233 218 219 183 175 181 192 211 235 253 313 395 438 478 641 992 1351 1692 2151 2553 2854 2828 2253 1818 1293 843 556 487 406 343 287 216 211 171 169 180 163 164 162 171 167 192 159 162 165 154 164 182 172 184 161 148 166 170 174 159 155 162 145 125 138 154 157 165 185 174 192 203 202 199 214 237 215 224 198 181 159 165 193 135 156 158 136 115 147 149 160 182 147 149 131 154 168 164 163 129 145 131 127 107 124 149 162 121 153 144 131 127 140 146 143 136 122 126 123 121 128 139 155 138 132 125 122 133 135 127 131 143 135 146 139 128 148 119 190 153 155 157 195 223 198 203 222 170 189 205 157 146 163 164 140 135 177 174 141 162 160 163 147 190 173 198 208 207 233 272 325 400 479 637 810 949 1121 1267 1369 1248 1066 861 626 478 353 289 272 245 228 212 179 190 202 242 283 245 238 237 271 262 265 244 222 188 201 169 176 169 169 191 172 197 184 195 201 211 246 274 282 333 419 525 615 756 870 1009 1048 955 780 656 560 407 343 319 260 208 187 161 134 145 149 150 133 132 140 125 136 152 136 140 142 141 124 152 140 142 153 150 127 148 140 119 146 144 151 153 139 141 141 155 115 126 134 111 119 136 118 126 118 115 116 114 112 126 123 132 138 124 127 136 130 125 132 130 118 135 138 145 136 118 112 114 108 124 128 120 108 101 126 147 125 116 141 97 119 123 107 132 150 134 154 121 141 146 149 150 165 183 152 161 190 178 162 192 189 182 172 190 181 181 168 181 188 207 217 251 312 378 497 639 824 1112 1529 2179 2924 3698 4318 4659 4409 3654 2802 1998 1333 910 675 476 398 333 299 264 273 230 239 235 257 190 289 297 300 299 329 461 536 665 1037 1195 1594 1887 2241 2403 2171 1819 1507 1070 707 462 346 307 280 240 225 195 197 199 181 179 171 153 151 141 160 182 165 177 178 193 205 214 229 231 256 285 376 455 551 740 893 1264 1656 2325 2857 3435 3588 3710 3148 2443 1696 1233 883 605 443 382 307 282 232 204 246 223 181 172 151 153 113 127 133 135 141 144 117 104 111 131 123 112 115 119 105 106 124 114 111 123 108 102 95 92 102 95 87 105 109 89 102 110 103 84 103 90 102 85 129 93 117 106 100 107 94 85 113 113 99 82 93 102 114 100 103 103 121 106 90 101 86 103 96 84 97 109 95 99 100 103 96 91 94 95 94 90 96 99 119 106 96 98 84 88 90 86 93 85 67 88 105 104 94 83 90 89 85 85 94 92 86 104 85 88 104 103 91 105 82 98 100 91 96 84 92 98 97 113 107 94 101 105 96 90 92 98 114 108 89 89 99 113 113 107 105 115 105 98 92 102 94 100 97 105 100 123 106 101 103 93 102 102 112 118 108 127 115 127 122 118 128 131 128 155 154 191 238 294 342 500 734 923 1072 1198 1143 975 777 542 387 273 246 210 200 190 214 225 261 295 313 383 427 410 372 305 264 224 168 142 119 116 123 95 114 102 90 93 93 104 112 100 102 102 111 88 103 94 91 99 97 88 90 103 85 85 91 94 110 89 92 112 101 95 102 98 106 96 89 92 94 96 106 96 103 105 100 98 97 95 91 89 89 108 128 108 105 119 116 113 119 127 122 137 152 164 197 182 230 245 302 315 470 573 723 1135 1502 2105 2657 3432 3978 4032 3464 2742 2115 1425 914 626 426 343 284 230 225 209 178 171 175 171 164 174 176 190 225 272 321 359 423 465 463 419 354 273 220 196 168 127 115 114 123 112 89 112 112 109 105 94 97 99 85 96 97 104 90 87 84 100 105 95 86 69 98 81 98 98 91 107 91 102 85 73 75 76 92 83 81 88 87 85 88 78 78 84 82 85 89 85 81 75 73 86 91 74 68 71 80 86 92 89 95 87 83 71 65 83 73 69 85 69 67 94 72 85 82 87 82 110 83 81 84 95 86 102 82 79 95 111 105 88 100 103 101 91 116 104 86 97 105 111 116 112 117 115 115 107 106 98 83 105 118 110 88 100 96 98 92 90 102 106 95 95 98 93 81 94 110 111 105 83 120 104 119 89 110 109 108 129 120 145 126 148 128 145 153 163 195 217 248 299 389 525 706 874 1060 1136 1094 962 817 634 473 344 241 194 174 158 145 140 119 112 118 110 103 111 123 99 95 109 113 108 123 94 107 106 120 144 147 180 209 233 258 290 328 338 359 364 290 270 206 196 147 136 116 121 115 104 102 113 112 89 88 96 114 101 104 101 88 96 102 92 85 105 100 106 99 87 84 96 103 88 96 100 94 92 99 104 93 85 93 97 78 87 96 89 75 93 100 84 104 104 106 102 91 100 119 114 94 117 104 106 148 194 198 246 340 453 589 650 676 605 562 449 326 253 189 158 168 160 169 184 203 244 300 412 586 773 929 1140 1147 1106 1000 810 641 423 288 224 184 178 141 134 145 104 128 100 92 108 127 136 95 85 109 98 100 94 102 101 97 104 111 104 105 110 119 119 116 111 99 99 118 129 121 120 124 131 150 168 183 219 261 309 394 558 705 870 1095 1232 1268 1213 1046 822 628 486 402 337 253 202 152 163 129 138 115 91 119 115 114 108 104 90 79 95 110 103 110 109 110 103 98 104 94 96 93 90 101 87 86 71 79 78 78 86 84 74 74 77 96 99 93 86 92 94 98 94 99 85 82 83 91 102 106 110 126 112 104 168 181 243 338 429 468 557 560 491 366 283 236 174 148 135 108 90 97 95 78 97 93 78 81 83 72 65 79 99 92 81 92 75 81 87 77 73 75 79 75 81 73 72 85 90 97 114 107 99 92 98 91 94 85 79 89 78 79 95 98 86 104 101 84 110 99 98 113 129 116 116 136 140 158 161 206 261 305 398 500 542 546 519 459 394 286 210 164 152 144 120 121 111 106 93 96 96 95 93 94 99 88 87 94 94 85 86 84 75 78 76 89 82 87 92 86 67 85 87 93 85 89 79 84 92 82 82 81 84 86 100 88 99 103 102 108 126 133 126 142 150 167 173 218 281 335 469 669 900 1186 1526 1746 1768 1562 1263 940 678 517 419 379 335 331 367 396 497 627 865 1134 1431 1727 1785 1718 1451 1104 837 587 439 327 260 231 208 162 190 176 140 155 147 158 118 111 110 118 117 113 115 115 103 93 100 105 92 91 89 90 84 90 100 87 82 90 98 111 104 97 110 105 121 139 151 173 227 268 314 335 352 387 383 406 352 286 237 214 166 130 115 99 108 94 97 91 88 85 101 88 90 91 76 87 95 98 90 93 96 91 70 81 83 76 67 74 71 78 74 81 82 68 70 73 67 77 89 88 81 76 78 80 85 76 75 77 74 73 78 71 65 50 74 74 71 74 96 70 69 83 72 70 67 72 83 78 69 80 85 75 84 78 67 69 76 70 69 68 82 70 70 76 72 68 74 86 83 76 77 76 86 86 83 84 92 88 77 75 77 87 92 81 89 81 77 80 73 82 94 85 72 75 79 73 73 68 60 58 64 95 75 75 79 73 82 95 98 88 109 122 124 120 108 127 123 113 132 167 197 219 281 341 425 431 393 349 261 216 177 143 131 114 103 94 85 76 92 91 89 91 83 81 89 86 80 75 79 76 83 80 80 74 68 68 81 84 91 62 53 78 70 77 69 78 72 70 82 92 100 112 97 103 107 121 105 89 98 87 73 76 74 74 79 87 85 85 86 81 73 74 76 74 72 66 89 89 77 75 79 89 83 79 94 80 84 83 79 66 64 69 78 85 71 104 88 73 69 74 67 68 77 69 72 68 77 74 80 84 89 79 88 78 98 100 109 102 111 135 138 125 132 120 103 103 96 105 105 91 92 90 97 99 84 80 86 77 68 79 93 97 77 80 85 91 79 78 81 91 86 79 80 76 63 75 87 67 78 69 84 86 81 83 85 88 84 80 77 83 81 80 93 103 94 105 92 97 127 161 175 219 258 307 353 363 345 301 237 182 153 129 104 99 104 103 107 98 90 91 87 89 88 94 88 88 99 93 95 95 99 96 88 106 115 133 149 176 205 253 321 351 395 348 325 270 205 180 154 125 113 90 104 97 86 90 94 93 97 95 91 83 79 92 94 96 91 97 95 99 103 96 96 91 89 100 94 80 71 67 78 84 83 86 68 84 82 68 81 71 70 72 76 72 78 62 69 78 83 81 80 71 59 80 67 75 76 73 65 74 74 78 86 82 93 89 78 84 80 84 86 82 93 106 113 105 112 110 122 136 174 216 269 348 421 503 494 433 378 351 300 279 280 281 350 405 501 605 653 717 650 546 417 335 278 196 162 127 128 112 121 99 106 107 86 109 105 86 94 86 77 97 111 92 90 90 83 86 97 92 90 97 94 92 84 97 106 104 105 116 111 124 139 185 195 217 287 387 450 452 456 397 336 301 287 260 294 313 377 491 553 582 539 462 432 326 254 192 143 125 118 101 100 102 89 85 86 88 89 88 84 80 82 89 90 84 77 69 74 81 86 80 71 79 78 77 74 81 87 87 76 82 83 77 81 77 79 66 85 74 75 84 82 78 79 81 65 71 78 77 66 59 62 72 76 69 79 65 83 80 80 70 77 78 82 72 77 75 80 88 91 95 95 94 87 82 88 89 91 96 86 71 76 93 90 85 79 77 92 99 90 78 113 113 128 141 166 182 174 181 180 151 166 121 124 99 106 90 81 75 81 72 76 76 73 76 70 57 77 76 80 90 84 80 80 79 80 75 74 81 81 76 83 90 73 73 89 87 88 80 87 96 95 102 100 97 105 105 117 141 142 173 201 245 355 453 552 658 724 759 685 584 503 385 342 309 266 274 302 347 456 570 623 708 738 698 602 511 422 340 272 198 166 160 158 160 164 175 192 217 242 263 287 299 286 259 223 184 174 164 143 126 121 116 117 131 141 140 155 151 185 178 224 266 323 418 522 662 734 788 745 632 533 416 322 249 230 175 160 128 122 121 137 120 110 118 96 97 108 110 91 105 106 106 102 104 97 102 105 105 99 93 100 105 107 118 118 124 134 144 139 163 151 162 177 206 234 265 333 398 441 577 849 1209 1629 2082 2474 2788 2874 2541 2074 1548 1108 755 541 430 359 293 264 224 213 208 194 178 168 157 141 128 115 114 115 114 113 111 116 110 106 111 117 106 100 103 109 120 106 96 107 105 113 120 133 148 155 146 159 158 192 219 246 269 334 409 523 655 899 1037 1273 1393 1422 1215 1009 792 608 454 373 302 261 226 206 215 240 247 244 218 180 171 148 135 125 108 97 112 113 95 90 94 94 95 90 91 96 97 86 83 88 88 87 86 81 87 89 84 70 84 89 87 91 84 86 88 102 108 112 118 136 150 142 132 107 110 114 97 78 77 82 79 61 73 76 78 74 81 84 81 82 75 81 76 77 83 89 80 84 95 94 94 102 123 121 111 113 107 91 93 91 85 75 88 70 68 75 81 64 69 66 67 75 80 65 64 77 59 71 69 60 70 67 78 67 55 77 75 73 76 63 60 54 58 52 60 72 69 64 62 60 57 66 74 75 70 65 75 75 77 63 57 61 65 69 72 73 67 59 71 67 63 64 76 66 72 58 70 75 77 83 96 91 85 107 120 136 163 170 169 141 151 147 132 137 154 192 203 247 243 199 200 174 140 112 102 101 92 86 83 86 81 71 66 63 71 83 80 77 74 69 72 74 76 77 77 79 72 76 79 81 81 85 84 70 72 71 91 83 80 102 109 114 136 134 143 121 111 105 110 100 104 94 97 98 109 115 111 123 118 97 93 76 73 78 72 69 73 71 68 68 74 72 68 78 80 75 72 70 70 73 79 78 74 70 69 78 78 69 78 68 66 70 76 70 64 63 88 69 72 70 102 98 93 75 99 113 104 128 155 175 211 255 271 289 290 272 241 184 157 129 104 92 88 88 88 93 86 83 85 77 76 77 76 73 66 64 77 74 77 83 81 72 72 78 77 83 70 75 87 86 101 106 106 123 128 170 169 200 225 244 226 172 158 130 111 115 90 78 86 83 82 88 84 85 74 69 72 69 72 72 70 72 70 65 67 81 86 71 76 82 77 77 69 75 85 83 84 73 94 93 107 100 101 97 121 156 171 221 277 308 359 341 308 287 237 203 193 200 212 249 299 352 423 453 462 374 320 253 189 154 147 121 111 99 106 98 94 93 98 93 97 95 97 93 89 91 82 85 89 83 77 75 66 66 73 70 71 76 72 83 80 68 68 79 68 69 63 70 64 82 69 68 66 72 73 66 69 73 73 64 63 74 68 82 64 56 60 58 53 65 68 62 71 66 65 69 69 67 70 71 66 66 79 78 67 65 78 75 63 68 61 59 65 75 75 70 91 80 83 82 94 89 96 97 106 116 122 113 116 141 163 199 264 305 362 394 397 424 361 293 248 189 172 155 134 119 108 102 104 102 86 85 90 82 83 87 83 78 70 72 76 82 80 75 76 82 83 81 85 84 85 81 90 101 104 131 120 135 135 154 146 154 147 155 139 153 182 217 246 229 243 189 182 158 123 109 99 75 108 82 95 90 86 80 79 78 86 80 78 77 77 72 63 68 75 76 72 77 74 72 78 81 80 78 83 95 92 100 118 138 143 163 199 285 259 254 253 215 201 191 178 211 230 243 240 235 210 158 141 121 99 97 84 82 78 77 77 89 82 74 77 67 67 73 75 69 74 81 74 65 65 72 67 64 58 66 71 71 65 64 65 66 56 59 55 59 63 55 62 63 58 70 65 64 64 66 73 62 59 70 70 64 62 62 64 70 69 63 81 60 58 66 76 85 75 62 65 67 66 67 63 68 65 63 71 73 75 75 70 73 77 86 87 93 98 91 86 104 108 115 130 125 126 137 122 131 148 170 195 232 280 345 411 465 450 454 418 356 281 227 200 175 146 123 109 105 103 113 117 121 145 133 137 138 119 105 99 95 92 80 91 82 84 79 77 79 78 75 76 81 91 100 96 98 118 109 93 95 101 85 82 82 85 83 72 63 72 74 75 70 52 56 64 63 66 68 59 56 74 70 62 60 69 64 65 75 65 61 61 58 65 71 62 82 83 71 70 78 76 83 82 81 90 100 113 128 143 153 161 154 148 135 120 123 134 135 155 185 214 253 270 233 227 202 150 134 111 102 101 99 101 90 83 83 83 73 78 79 67 73 69 70 75 70 74 68 72 71 64 77 73 73 72 84 87 82 82 82 94 109 119 128 135 139 142 146 149 130 108 91 95 88 70 69 78 84 79 79 77 78 69 66 71 65 67 75 63 73 62 62 77 79 72 75 83 68 69 81 76 79 78 78 76 81 80 78 76 85 98 123 133 153 181 202 239 240 230 212 189 165 147 123 110 104 100 111 106 116 120 105 103 107 98 90 84 78 71 78 75 62 63 66 76 70 72 66 70 71 79 68 73 65 62 75 74 68 67 76 79 81 79 69 76 83 86 93 101 105 115 127 131 147 154 153 146 149 167 172 177 194 224 243 245 249 246 217 181 157 140 122 120 110 96 87 92 95 92 89 80 91 79 69 64 74 71 71 78 69 77 72 66 70 73 74 76 80 78 74 68 74 80 68 69 75 78 101 96 117 147 160 182 225 286 309 303 295 272 236 184 146 130 116 95 99 101 97 89 97 114 115 112 121 111 110 103 108 102 91 84 84 77 82 75 74 70 77 74 71 63 72 71 74 77 76 80 78 63 67 80 79 70 76 77 67 70 79 69 60 62 65 73 69 74 66 69 71 71 74 74 68 78 80 80 83 78 84 92 90 85 75 81 95 96 92 104 118 123 120 141 168 166 192 235 279 352 443 504 576 588 551 471 406 326 305 248 241 241 228 259 303 328 357 334 316 273 228 208 161 132 132 128 110 106 102 103 105 95 98 100 101 102 97 88 84 83 80 81 81 86 88 92 88 98 106 107 116 134 159 170 179 202 227 253 223 214 178 177 172 193 203 226 248 254 268 252 227 163 171 150 133 110 96 95 96 96 87 102 107 106 106 107 99 92 83 75 72 79 79 80 73 66 70 73 80 78 80 70 60 75 96 92 105 124 128 132 138 170 153 127 136 108 101 86 79 79 85 68 79 66 63 76 73 71 64 72 72 72 66 72 68 74 61 65 65 65 77 75 72 68 71 70 79 83 74 74 72 75 74 72 75 80 75 75 88 100 106 112 126 123 136 132 128 135 128 104 96 87 81 90 76 71 75 58 73 67 72 75 82 93 88 83 111 139 143 142 135 121 105 96 92 81 77 81 73 61 70 71 65 57 60 68 66 62 58 59 64 68 63 62 64 66 61 62 58 59 59 56 66 63 65 50 52 70 63 61 53 60 63 55 69 60 53 68 68 59 65 62 66 60 63 66 56 64 56 64 65 64 65 61 55 56 61 58 63 68 54 48 58 63 61 57 60 71 71 66 60 58 63 63 55 53 57 61 60 59 64 64 62 63 61 65 63 55 61 63 68 74 74 58 69 63 52 61 65 60 63 62 70 64 60 67 59 66 69 51 56 64 63 69 75 77 84 84 85 92 102 99 97 108 121 125 128 149 167 193 203 211 218 204 181 165 141 118 103 108 91 96 92 108 113 116 119 128 139 139 143 130 142 127 113 100 85 84 81 86 81 81 80 69 77 74 78 84 73 75 82 96</intensities>
			</dataPoints>
			<nonAmbientPoints type="Temperature" unit="K">
				<measurementTimes unit="seconds" deltaTime="1">0</measurementTimes>
				<nonAmbientValues>298.000</nonAmbientValues>
			</nonAmbientPoints>
		</scan>
	</xrdMeasurement>
</xrdMeasurements>